<!-- Author + Copyright (C) Aravind Rajeswaran, rajeswaran.aravind@gmail.com.
See LICENSE file for legal notices. LICENSE must be kept together with this file. -->
<mujoco model="PointMass">
    <compiler inertiafromgeom="true" angle="radian" />
    <default>
        <joint armature="0.0" damping="0.0" limited="true"/>
        <geom friction="0.5 0.5 0.5" rgba="0.7 0.7 0 1"/>
        <motor ctrllimited="true" ctrlrange="-5.0 5.0" />
    </default>
    <option gravity="0 0 -9.81" integrator="RK4" timestep="0.01"/>


    <worldbody>
        <!-- Arena -->
        <geom name="ground" pos="0 0 0" rgba="0.8 0.8 0.8 1" size="5 5 0.1" type="plane" mass="10" priority="0"/>
        <geom fromto="-5 -5 .02  5 -5 .02" name="sideS" rgba="0.3 0.4 0.3 1.0" size=".04" type="capsule" mass="10"/>
        <geom fromto=" 5 -5 .02  5  5 .02" name="sideE" rgba="0.3 0.4 0.3 1.0" size=".04" type="capsule" mass="10"/>
        <geom fromto="-5  5 .02  5  5 .02" name="sideN" rgba="0.3 0.4 0.3 1.0" size=".04" type="capsule" mass="10"/>
        <geom fromto="-5 -5 .02 -5  5 .02" name="sideW" rgba="0.3 0.4 0.3 1.0" size=".04" type="capsule" mass="10"/>

        <!-- Agent -->
        <body name="agent" pos="0 0 0.05">
            <joint axis="1 0 0" name="agent_x" pos="0 0 0" range="-10 10" stiffness="0" type="slide"/>
            <joint axis="0 1 0" name="agent_y" pos="0 0 0" range="-10 10" stiffness="0" type="slide"/>
            <joint axis="0 0 1" name="agent_z" pos="0 0 0" range="-10 10" stiffness="0" type="slide"/>
            <geom name="agent" pos="0 0 0" rgba="0.2 0.2 0.6 1" size=".05" type="sphere" contype="3"/>
        </body>

        <!-- Target -->
        <site name="target" pos="1.0 0 .1" rgba="0.6 0.2 0.2 0.2" size=".07" type="sphere" />

    </worldbody>

    <actuator>
        <motor gear="1.0" joint="agent_x"/>
    </actuator>

</mujoco>
